<?xml version="1.0"?>
<!-- Open_Manipulator Chain -->
<robot name="open_manipulator" xmlns:xacro="http://www.ros.org/wiki/xacro">

<!-- Import all Gazebo-customization elements, including Gazebo colors -->
  <xacro:include filename="$(find open_manipulator_support_description)/urdf/open_manipulator.gazebo.xacro"/>
<!-- Import Rviz colors -->
  <xacro:include filename="$(find open_manipulator_support_description)/urdf/materials.xacro" />
<!-- Import inertial Properties-->
  <xacro:include filename="$(find open_manipulator_support_description)/urdf/inertial_properties.xacro" />
<!-- Import inertial Properties-->
  <xacro:include filename="$(find open_manipulator_support_description)/urdf/mass_properties.xacro" />
<!-- Import Sensors-->
  <xacro:include filename="$(find open_manipulator_support_description)/urdf/sensors.xacro" />
  <!-- Import realsense camera -->
  <xacro:include filename="$(find realsense_description)/urdf/realsense_d435.urdf.xacro" />

<!-- Camera Link -->
  <xacro:realsense_macro parent="link6" name="realsense_d435" hz="6">
    <origin xyz="0 -0.1 0" rpy="3.1416 -1.57079632679 -1.57079632679"/>
  </xacro:realsense_macro>

  <gazebo reference="camera_link">
      <sensor type="depth" name="camera1">
      <update_rate>20.0</update_rate>
      <camera name="head">
          <horizontal_fov>1.3962634</horizontal_fov>
          <image>
            <width>640</width>
            <height>480</height>
            <format>R8G8B8</format>
          </image>
          <clip>
            <near>0.05</near>
            <far>3</far>
          </clip>
          <noise>
          <type>gaussian</type>
          <!-- Noise is sampled independently per pixel on each frame.
            That pixel's noise value is added to each of its color
            channels, which at that point lie in the range [0,1]. -->
          <mean>0.0</mean>
          <stddev>0.007</stddev>
          </noise>
      </camera>
      <plugin name="camera_controller" filename="libgazebo_ros_openni_kinect.so">
          <baseline>0.2</baseline>
          <alwaysOn>true</alwaysOn>
          <updateRate>1.0</updateRate>
          <cameraName>realsense/camera1</cameraName>
          <imageTopicName>image_raw</imageTopicName>
          <cameraInfoTopicName>camera_info</cameraInfoTopicName>
          <depthImageTopicName>depth/image_raw</depthImageTopicName>
          <depthImageInfoTopicName>depth/camera_info</depthImageInfoTopicName>
          <pointCloudTopicName>depth/points</pointCloudTopicName>
          <frameName>camera_link</frameName>
          <pointCloudCutoff>0.5</pointCloudCutoff>
          <pointCloudCutoffMax>3.0</pointCloudCutoffMax>
          <hackBaseline>0</hackBaseline>
          <distortionK1>0.0</distortionK1>
          <distortionK2>0.0</distortionK2>
          <distortionK3>0.0</distortionK3>
          <distortionT1>0.0</distortionT1>
          <distortionT2>0.0</distortionT2>
          <CxPrime>0</CxPrime>
          <Cx>0</Cx>
          <Cy>0</Cy>
          <focalLength>0</focalLength>
      </plugin>
      </sensor>
  </gazebo>   


 <!-- World -->
   <link name="world">
   </link>



<!-- Floor Link -->
  <link name="floor_link">
	 <inertial>
      <mass value="${bl_mass}" />
      <origin xyz="${bl_cmx} ${bl_cmy} ${bl_cmz}"/>
      <inertia
        ixx="${bl_ixx}"
        ixy="${bl_ixy}"
        ixz="${bl_ixz}"
        iyy="${bl_iyy}"
        iyz="${bl_iyz}"
        izz="${bl_izz}" />
    </inertial>
	<visual>
		<geometry>
        	<mesh filename="package://realrobotlab/models/robotarm_floor_v1/meshes/robotarm_floor_v1.dae"/>
		</geometry>
	</visual>
	<collision>
      <geometry>
          <mesh filename="package://realrobotlab/models/robotarm_floor_v1/meshes/robotarm_floor_v1.dae"/>
      </geometry>
    </collision>
  </link>

  <!-- World fixed joint -->
   <joint name="world_fixed" type="fixed">
     <parent link="world"/>
     <child link="floor_link"/>
   </joint>


<!-- Base Plate Link -->
  <link name="base_plate_link">
	 <inertial>
      <mass value="${bl_mass}" />
      <origin xyz="${bl_cmx} ${bl_cmy} ${bl_cmz}"/>
      <inertia
        ixx="${bl_ixx}"
        ixy="${bl_ixy}"
        ixz="${bl_ixz}"
        iyy="${bl_iyy}"
        iyz="${bl_iyz}"
        izz="${bl_izz}" />
    </inertial>
	<visual>
		<geometry>
        	<mesh filename="package://open_manipulator_support_description/meshes/base_plate.stl"/>
		</geometry>
    <material name="white"/>
	</visual>
	<collision>
      <geometry>
          <mesh filename="package://open_manipulator_support_description/meshes/base_plate.stl"/>
      </geometry>
    </collision>
  </link>


  <!-- World fixed joint -->
   <joint name="base_plate_fixed" type="fixed">
      <origin rpy="0 0 -1.57" xyz="0 0 0"/>
      <parent link="floor_link"/>
      <child link="base_plate_link"/>
   </joint>

<!-- Base Link -->
  <link name="base_link">
	 <inertial>
      <mass value="${bl_mass}" />
      <origin xyz="${bl_cmx} ${bl_cmy} ${bl_cmz}"/>
      <inertia
        ixx="${bl_ixx}"
        ixy="${bl_ixy}"
        ixz="${bl_ixz}"
        iyy="${bl_iyy}"
        iyz="${bl_iyz}"
        izz="${bl_izz}" />
    </inertial>
	<visual>
		<geometry>
        	<mesh filename="package://open_manipulator_support_description/meshes/base_link.STL"/>
		</geometry>
    <material name="grey"/>
	</visual>
	<collision>
      <geometry>
        <mesh filename="package://open_manipulator_support_description/meshes/base_link.STL" />
      </geometry>
    </collision>
  </link>


    <!-- World fixed joint -->
   <joint name="base_fixed" type="fixed">
      <origin rpy="0 0 0" xyz="0 0 0.014"/>
      <parent link="base_plate_link"/>
      <child link="base_link"/>
   </joint>


<!-- Link 1 --> 
  <link name="link1">
    <visual>
      <geometry>
        <mesh filename="package://open_manipulator_support_description/meshes/link1.STL"/>
      </geometry>
      <material name="grey"/>
    </visual>

    <collision>
      <geometry>
        <mesh filename="package://open_manipulator_support_description/meshes/link1.STL"/>
      </geometry>
    </collision>

	<inertial>
      <mass value="${l1_mass}" />
      <origin xyz="${l1_cmx} ${l1_cmy} ${l1_cmz}"/>
      <inertia
        ixx="${l1_ixx}"
        ixy="${l1_ixy}"
        ixz="${l1_ixz}"
        iyy="${l1_iyy}"
        iyz="${l1_iyz}"
        izz="${l1_izz}" />
    </inertial>
  </link>

<!-- Joint 1 -->
  <joint name="id_1" type="revolute">
    <parent link="base_link"/>
    <child link="link1"/>
    <origin xyz="0 0 0.0405"/>
    <axis xyz="0 0 1"/>
    <limit  effort="150.0" velocity="3.15" lower="${-1.1*pi}" upper="${0.9*pi}" />
  </joint>

<!-- Transmission 1 -->
  <transmission name="tran1">
    <type>transmission_interface/SimpleTransmission</type>
    <joint name="id_1">
      <hardwareInterface>hardware_interface/PositionJointInterface</hardwareInterface>
    </joint>
    <actuator name="motor1">
      <hardwareInterface>hardware_interface/PositionJointInterface</hardwareInterface>
      <mechanicalReduction>1</mechanicalReduction>
    </actuator>
  </transmission>

<!--  Link 2-->
  <link name="link2">
    
	<visual>
      <geometry>
        <mesh filename="package://open_manipulator_support_description/meshes/link2.STL"/>
      </geometry>
      <material name="grey"/>
    </visual>

    <collision>
      <geometry>
        <mesh filename="package://open_manipulator_support_description/meshes/link2.STL"/>
      </geometry>
    </collision>

    <inertial>
      <mass value="${l2_mass}" />
      <origin xyz="${l2_cmx} ${l2_cmy} ${l2_cmz}"/>
      <inertia 
        ixx="${l2_ixx}"
        ixy="${l2_ixy}"
        ixz="${l2_ixz}"
        iyy="${l2_iyy}"
        iyz="${l2_iyz}"
        izz="${l2_izz}" />
    </inertial>
  </link>

<!--  Joint 2 -->
  <joint name="id_2" type="revolute">
    <parent link="link1"/>
    <child link="link2"/>
    <origin xyz="0 0 0.056"/>
    <axis xyz="1 0 0"/>
    <limit  effort="150.0" velocity="3.15" lower="-2.0" upper="2.0" />
  </joint>
  
<!-- Transmission 2 -->
  <transmission name="tran2">
    <type>transmission_interface/SimpleTransmission</type>
    <joint name="id_2">
      <hardwareInterface>hardware_interface/PositionJointInterface</hardwareInterface>
    </joint>
    <actuator name="motor2">
      <hardwareInterface>hardware_interface/PositionJointInterface</hardwareInterface>
      <mechanicalReduction>1</mechanicalReduction>
    </actuator>
  </transmission>

<!--  Link 3 -->
  <link name="link3">
    <visual>
      <geometry>
        <mesh filename="package://open_manipulator_support_description/meshes/link3.STL"/>
      </geometry>
      <material name="grey"/>
    </visual>
    <collision>
      <geometry>
        <mesh filename="package://open_manipulator_support_description/meshes/link3.STL"/>
      </geometry>
    </collision>

    <inertial>
      <mass value="${l3_mass}" />
      <origin xyz="${l3_cmx} ${l3_cmy} ${l3_cmz}"/>
      <inertia 
        ixx="${l3_ixx}"
        ixy="${l3_ixy}"
        ixz="${l3_ixz}"
        iyy="${l3_iyy}"
        iyz="${l3_iyz}"
        izz="${l3_izz}" />
    </inertial>
  </link>

<!--  Joint 3 -->
  <joint name="id_3" type="revolute">
    <parent link="link2"/>
    <child link="link3"/>
    <origin xyz="0 0 .1935" />
    <axis xyz="1 0 0"/>
    <limit  effort="150.0" velocity="3.15" lower="-2.5" upper="2.5" />
  </joint>

<!-- Transmission 3 -->
  <transmission name="tran3">
    <type>transmission_interface/SimpleTransmission</type>
    <joint name="id_3">
      <hardwareInterface>hardware_interface/PositionJointInterface</hardwareInterface>
    </joint>
    <actuator name="motor3">
      <hardwareInterface>hardware_interface/PositionJointInterface</hardwareInterface>
      <mechanicalReduction>1</mechanicalReduction>
    </actuator>
  </transmission>

<!--  Link 4 -->
  <link name="link4">
    <visual>
      <geometry>
        <mesh filename="package://open_manipulator_support_description/meshes/link4.STL"/>
      </geometry>
      <material name="grey"/>
    </visual>

    <collision>
      <geometry>
        <mesh filename="package://open_manipulator_support_description/meshes/link4.STL"/>
      </geometry>
    </collision>

    <inertial>
      <mass value="${l4_mass}" />
      <origin xyz="${l4_cmx} ${l4_cmy} ${l4_cmz}"/>
      <inertia 
        ixx="${l4_ixx}"
        ixy="${l4_ixy}"
        ixz="${l4_ixz}"
        iyy="${l4_iyy}"
        iyz="${l4_iyz}"
        izz="${l4_izz}" />
    </inertial>

  </link>

<!--  Joint 4-->
  <joint name="id_4" type="revolute">
    <parent link="link3"/>
    <child link="link4"/>
    <origin xyz="0 0 0.201"/>
    <axis xyz="0 0 1"/>
    <limit  effort="150.0" velocity="3.15" lower="${-pi}" upper="${pi}" />
  </joint>

<!-- Transmission 4 -->
  <transmission name="tran4">
    <type>transmission_interface/SimpleTransmission</type>
    <joint name="id_4">
      <hardwareInterface>hardware_interface/PositionJointInterface</hardwareInterface>
    </joint>
    <actuator name="motor4">
      <hardwareInterface>hardware_interface/PositionJointInterface</hardwareInterface>
      <mechanicalReduction>1</mechanicalReduction>
    </actuator>
  </transmission>

<!--  Link 5 -->
  <link name="link5">
    <visual>
      <geometry>
        <mesh filename="package://open_manipulator_support_description/meshes/link5.STL"/>
      </geometry>
      <material name="grey"/>
    </visual>

    <collision>
      <geometry>
        <mesh filename="package://open_manipulator_support_description/meshes/link5.STL"/>
      </geometry>
    </collision>

    <inertial>
      <mass value="${l5_mass}" />
      <origin xyz="${l5_cmx} ${l5_cmy} ${l5_cmz}"/>
      <inertia
        ixx="${l5_ixx}"
        ixy="${l5_ixy}"
        ixz="${l5_ixz}"
        iyy="${l5_iyy}"
        iyz="${l5_iyz}"
        izz="${l5_izz}" />
    </inertial>
  </link>

<!--  Joint 5-->
  <joint name="id_5" type="revolute">
    <parent link="link4"/>
    <child link="link5"/>
    <origin xyz="0 0 0.0405"/>
    <axis xyz="1 0 0"/>
    <limit  effort="150.0" velocity="3.15" lower="${-pi/2}" upper="2.2" />
  </joint>

<!-- Transmission 5 -->
  <transmission name="tran5">
    <type>transmission_interface/SimpleTransmission</type>
    <joint name="id_5">
      <hardwareInterface>hardware_interface/PositionJointInterface</hardwareInterface>
    </joint>
    <actuator name="motor5">
      <hardwareInterface>hardware_interface/PositionJointInterface</hardwareInterface>
      <mechanicalReduction>1</mechanicalReduction>
    </actuator>
  </transmission>

  
  
<!--  Link 6 -->
  <link name="link6">
    <inertial>
      <mass value="${l6_mass}" />
      <origin xyz="${l6_cmx} ${l6_cmy} ${l6_cmz}"/>
      <inertia
        ixx="${l6_ixx}"
        ixy="${l6_ixy}"
        ixz="${l6_ixz}"
        iyy="${l6_iyy}"
        iyz="${l6_iyz}"
        izz="${l6_izz}" />
    </inertial>
    <visual>
      <geometry>
        <mesh filename="package://open_manipulator_support_description/meshes/link6.STL" />
      </geometry>
      <material name="grey" />
    </visual>
    <collision>
      <geometry>
        <mesh filename="package://open_manipulator_support_description/meshes/link6.STL" />
      </geometry>
    </collision>
  </link>

<!--  Joint 6 -->
  <joint name="id_6" type="revolute">
    <origin xyz="0 0 0.064"/>
    <parent link="link5" />
    <child link="link6" />
    <axis xyz="0 0 1" />
	<limit  effort="150.0" velocity="3.15" lower="${-pi}" upper="${pi}" />
  </joint>

<!-- Transmission 6 -->
  <transmission name="tran6">
    <type>transmission_interface/SimpleTransmission</type>
    <joint name="id_6">
      <hardwareInterface>hardware_interface/PositionJointInterface</hardwareInterface>
    </joint>
    <actuator name="motor6">
      <hardwareInterface>hardware_interface/PositionJointInterface</hardwareInterface>
      <mechanicalReduction>1</mechanicalReduction>
    </actuator>
  </transmission>  
 
<!-- Link 7-->
   <link name="link7">
    <inertial>
      <mass value="${l7_mass}" />
      <origin xyz="${l7_cmx} ${l7_cmy} ${l7_cmz}"/>
      <inertia
        ixx="${l7_ixx}"
        ixy="${l7_ixy}"
        ixz="${l7_ixz}"
        iyy="${l7_iyy}"
        iyz="${l7_iyz}"
        izz="${l7_izz}" />
    </inertial>
    <visual>
      <geometry>
        <mesh
          filename="package://open_manipulator_support_description/meshes/link7.STL" />
      </geometry>
      <material name="grey" />
    </visual>
    <collision>
      <geometry>
        <mesh
          filename="package://open_manipulator_support_description/meshes/link7.STL" />
      </geometry>
    </collision>
  </link>


<!-- GRIPPER PART -->



<!-- Joint 7 -->
	<joint
    name="id_7"
    type="revolute">
    <origin xyz="0 0 0.039" />
    <parent link="link6" />
    <child link="link7" />
    <axis xyz="0 0 1" />
    <limit  effort="150.0" velocity="3.15" lower="${-pi}" upper="${pi}" />
  </joint>

  <!-- Transmission 7 --> 
  <transmission name="tran7">
    <type>transmission_interface/SimpleTransmission</type>
    <joint name="id_7">
      <hardwareInterface>hardware_interface/PositionJointInterface</hardwareInterface>
    </joint>
    <actuator name="motor7">
      <hardwareInterface>hardware_interface/PositionJointInterface</hardwareInterface>
      <mechanicalReduction>1</mechanicalReduction>
    </actuator>
  </transmission>

<!--  Gripper Left--> 
  
<link name="gripper_l">
    <inertial>
      <mass value="${g_mass}" />
      <origin xyz="${g_cmx} ${g_cmy} ${g_cmz}"/>
      <inertia
        ixx="${g_ixx}"
        ixy="${g_ixy}"
        ixz="${g_ixz}"
        iyy="${g_iyy}"
        iyz="${g_iyz}"
        izz="${g_izz}" />
    </inertial>
    
    <visual>
      <geometry>
        <mesh
          filename="package://open_manipulator_support_description/meshes/gripper.STL" />
      </geometry>
      <material name="grey" />
    </visual>
    
   <collision>
      <geometry>
        <!-- <mesh
          filename="package://open_manipulator_support_description/meshes/gripper.STL" /> -->
          <!-- <cylinder length="0.0923" radius="0.0132055"/> -->
          <box size="0.026411 0.026411 0.0923"/>
      </geometry>
    </collision> 
  </link>

<!--Gripper Left Joint -->
  <joint name="joint8" type="prismatic">
    <origin xyz="-0.015 0 0.0595" rpy="0 0 ${pi}"/>
    <parent link="link6" />
    <child link="gripper_l" />
    <axis xyz="-1 0 0" />
    <limit velocity="0.0525" effort="100.0" lower="-0.033" upper="0"/>
    <dynamics friction="100" damping="100" />
    <!-- <mimic joint="id_7" multiplier="-0.01" offset="-0.0110133334" />  -->
  </joint> 


  <!-- Transmission Gripper -->
  <transmission name="tranGripper_L">
    <type>transmission_interface/SimpleTransmission</type>
    <joint name="joint8">
      <hardwareInterface>hardware_interface/PositionJointInterface</hardwareInterface>
    </joint>
    <actuator name="motorGripper_L">
      <hardwareInterface>hardware_interface/PositionJointInterface</hardwareInterface>
      <mechanicalReduction>1</mechanicalReduction>
      <motorTorqueConstant>1</motorTorqueConstant>
    </actuator>
  </transmission>

  <!-- <xacro:mimic_joint_plugin_gazebo name_prefix="joint8"
    parent_joint="id_7" mimic_joint="joint8"
    has_pid="true" multiplier="1.0" max_effort="10.0" /> -->


<!--  Gripper Right --> 
   <link name="gripper_r">
    <inertial>
      <mass value="${g_mass}" />
      <origin xyz="${-g_cmx} ${g_cmy} ${g_cmz}"/>
      <inertia
        ixx="${g_ixx}"
        ixy="${g_ixy}"
        ixz="${g_ixz}"
        iyy="${g_iyy}"
        iyz="${g_iyz}"
        izz="${g_izz}" />
    </inertial>
        <visual>
      <geometry>
        <mesh filename="package://open_manipulator_support_description/meshes/gripper.STL" />
      </geometry>
      <material name="grey" />
    </visual>
    
    <collision>
      <geometry>
        <!-- <mesh filename="package://open_manipulator_support_description/meshes/gripper.STL" /> -->
        <!-- <cylinder length="0.0923" radius="0.0132055"/> -->
        <box size="0.026411 0.026411 0.0923"/>
      </geometry>
    </collision> 
  </link>
  
<!--Gripper Right Joint -->
   <joint name="joint9" type="prismatic">
    <origin xyz="0.015 0 0.0595" />
    <parent link="link6" />
    <child link="gripper_r" />
    <axis xyz="-1 0 0" />
    <limit velocity="0.0525" effort="100.0" lower="-0.033" upper="0.0"/>
    <dynamics friction="100" damping="100" />
    <mimic joint="joint8" multiplier="1.0" offset="0" />
    <!-- <mimic joint="joint8" multiplier="1" offset="0" /> -->
  </joint>

  <!-- MIMIC Transmission Gripper -->
  <transmission name="tranGripper_R">
    <type>transmission_interface/SimpleTransmission</type>
    <joint name="joint9">
      <hardwareInterface>hardware_interface/PositionJointInterface</hardwareInterface>
    </joint>
    <actuator name="motorGripper_R">
      <hardwareInterface>hardware_interface/PositionJointInterface</hardwareInterface>
      <mechanicalReduction>1</mechanicalReduction>
      <motorTorqueConstant>1</motorTorqueConstant>
    </actuator>
  </transmission>

  <!-- ros_control plugin -->
  <xacro:macro name="mimic_joint_plugin_gazebo" params="parent_joint mimic_joint has_pid:=false multiplier:=1.0 offset:=0 sensitiveness:=0.0 max_effort:=200.0 robot_namespace:=''">
      <gazebo>
          <plugin name="${mimic_joint}_mimic_joint_plugin" filename="libroboticsgroup_gazebo_mimic_joint_plugin.so">
              <joint>${parent_joint}</joint>
              <mimicJoint>${mimic_joint}</mimicJoint>
              <xacro:if value="${has_pid}">
              <hasPID />
              </xacro:if>
              <multiplier>${multiplier}</multiplier>
              <offset>${offset}</offset>
              <sensitiveness>${sensitiveness}</sensitiveness>
              <maxEffort>${max_effort}</maxEffort>
              <xacro:unless value="${robot_namespace == ''}">
                  <robotNamespace>($robot_namespace)</robotNamespace>
              </xacro:unless>
          </plugin>
      </gazebo>
  </xacro:macro>


  <xacro:mimic_joint_plugin_gazebo parent_joint="joint8"
    mimic_joint="joint9" has_pid="false" multiplier="1.0"
    max_effort="200.0" />

  <gazebo>
      <plugin name="gazebo_grasp_fix" filename="libgazebo_grasp_fix.so">
          <arm>
              <arm_name>arm</arm_name>
              <palm_link>link6</palm_link>
              <gripper_link> gripper_l </gripper_link>
              <gripper_link> gripper_r </gripper_link>
          </arm>
          <forces_angle_tolerance>100</forces_angle_tolerance>
          <update_rate>10</update_rate>
          <grip_count_threshold>3</grip_count_threshold>
          <max_grip_count>10</max_grip_count>
          <release_tolerance>0.001</release_tolerance>
          <disable_collisions_on_attach>false</disable_collisions_on_attach>
          <contact_topic>__default_topic__</contact_topic>
      </plugin>
  </gazebo>


</robot>
